from fastapi import FastAPI, HTTPException
from pydantic import BaseModel
from fastapi.middleware.cors import CORSMiddleware

app = FastAPI()

origins = [
    "http://localhost",
    "http://192.168.77.142",
]

app.add_middleware(
    CORSMiddleware,
    allow_origins=origins,
    allow_credentials=True,
    allow_methods=["*"],
    allow_headers=["*"],
)


class TodoItem(BaseModel):
    id: int
    content: str


class TodoItemCreate(BaseModel):
    content: str


todos: list[TodoItem] = []
id_counter = 1


@app.post("/todos", response_model=TodoItem)
async def create_todo(item: TodoItemCreate):
    global id_counter
    new_todo = TodoItem(id=id_counter, content=item.content)
    id_counter += 1
    todos.append(new_todo)
    return new_todo


@app.get("/todos", response_model=list[TodoItem])
async def read_todos():
    return todos


@app.delete("/todos/{todo_id}")
async def delete_todo(todo_id: int):
    for index, todo in enumerate(todos):
        if todo.id == todo_id:
            todos.pop(index)
            return {"message": "Todo deleted successfully"}
    raise HTTPException(status_code=404, detail="Todo not found")
